
<?xml version="0.0" ?>
<robot name="">
	<link name="frame">
		<inertial>
			<origin rpy="1.57080 -0.00000 1.57080" xyz="0.29000 0.00000 0.00000"/>
			<mass value="7.85398"/>
			<inertia ixx="0.50292" ixy="0" ixz="0" iyy="0.34584" iyz="0" izz="0.17017"/>
		</inertial>
		<visual>
			<origin rpy="0.00000 -0.00000 0.00000" xyz="0.60000 0.00000 0.00000"/>
			<geometry>
				<cylinder length="0.50000" radius="0.05000"/>
			</geometry>
			<material name="mat_-1_0">
				<color rgba="0.23438 0.72656 0.32812 1.00000" />
			</material>
		</visual>
		<visual>
			<origin rpy="0.00000 -0.00000 0.00000" xyz="-0.02000 0.00000 0.00000"/>
			<geometry>
				<cylinder length="0.50000" radius="0.05000"/>
			</geometry>
			<material name="mat_-1_1">
				<color rgba="0.23438 0.72656 0.32812 1.00000" />
			</material>
		</visual>
		<collision>
			<origin rpy="0.00000 -0.00000 0.00000" xyz="0.60000 0.00000 0.00000"/>
			<geometry>
				<cylinder length="0.50000" radius="0.05000"/>
			</geometry>
		</collision>
		<collision>
			<origin rpy="0.00000 -0.00000 0.00000" xyz="-0.02000 0.00000 0.00000"/>
			<geometry>
				<cylinder length="0.50000" radius="0.05000"/>
			</geometry>
		</collision>
	</link>
	<link name="link0_2">
		<inertial>
			<origin rpy="0.00000 -0.00000 0.00000" xyz="0.00000 0.00000 0.00000"/>
			<mass value="0.00000"/>
			<inertia ixx="0.00000" ixy="0" ixz="0" iyy="0.00000" iyz="0" izz="0.00000"/>
		</inertial>
	</link>
	<link name="door">
		<inertial>
			<origin rpy="0.00000 -0.00000 1.58779" xyz="0.02968 -0.00152 0.00000"/>
			<mass value="2.43455"/>
			<inertia ixx="0.10177" ixy="0" ixz="0" iyy="0.05311" iyz="0" izz="0.05344"/>
		</inertial>
		<visual>
			<origin rpy="0.00000 -0.00000 0.00000" xyz="0.00000 0.00000 0.00000"/>
			<geometry>
				<box size="0.40000 0.1000 0.5000"/>
			</geometry>
			<material name="mat_1_0">
				<color rgba="0.95312 0.75781 0.05078 1.00000" />
			</material>
		</visual>
		<visual>
			<origin rpy="0.00000 -0.00000 0.00000" xyz="0.20000 0.00000 0.00000"/>
			<geometry>
				<cylinder length="0.50000" radius="0.05000"/>
			</geometry>
			<material name="mat_1_1">
				<color rgba="0.95312 0.75781 0.05078 1.00000" />
			</material>
		</visual>
		<visual>
			<origin rpy="0.00000 -0.00000 0.00000" xyz="-0.20000 0.00000 0.00000"/>
			<geometry>
				<cylinder length="0.50000" radius="0.05000"/>
			</geometry>
			<material name="mat_1_2">
				<color rgba="0.95312 0.75781 0.05078 1.00000" />
			</material>
		</visual>
		<collision>
			<origin rpy="0.00000 -0.00000 0.00000" xyz="0.00000 0.00000 0.00000"/>
			<geometry>
				<box size="0.40000 0.10000 0.50000"/>
			</geometry>
		</collision>
		<collision>
			<origin rpy="0.00000 -0.00000 0.00000" xyz="0.20000 -0.00000 0.00000"/>
			<geometry>
				<cylinder length="0.50000" radius="0.05000"/>
			</geometry>
		</collision>
		<collision>
			<origin rpy="0.00000 -0.00000 0.00000" xyz="-0.20000 0.00000 0.00000"/>
			<geometry>
				<cylinder length="0.50000" radius="0.05000"/>
			</geometry>
		</collision>
	</link>
	<link name="link0_4">
		<inertial>
			<origin rpy="0.00000 -0.00000 0.00000" xyz="0.00000 0.00000 0.00000"/>
			<mass value="0.00000"/>
			<inertia ixx="0.00000" ixy="0" ixz="0" iyy="0.00000" iyz="0" izz="0.00000"/>
		</inertial>
	</link>
	<link name="latch">
		<inertial>
			<origin rpy="0.98613 -1.57018 1.06923" xyz="-0.01776 0.01385 0.00000"/>
			<mass value="3.53743"/>
			<inertia ixx="0.09155" ixy="0" ixz="0" iyy="0.06936" iyz="0" izz="0.02810"/>
		</inertial>
		<visual>
			<origin rpy="1.57000 -0.00000 0.00000" xyz="0.00000 0.00000 0.00000"/>
			<geometry>
				<cylinder length="0.30000" radius="0.05000"/>
			</geometry>
			<material name="mat_3_0">
				<color rgba="0.28125 0.51953 0.92578 1.00000" />
			</material>
		</visual>
		<visual>
			<origin rpy="0.00000 1.57000 0.00000" xyz="0.10000 -0.15000 0.00000"/>
			<geometry>
				<cylinder length="0.20000" radius="0.02000"/>
			</geometry>
			<material name="mat_3_1">
				<color rgba="0.28125 0.51953 0.92578 1.00000" />
			</material>
		</visual>
		<visual>
			<origin rpy="0.00000 1.57000 0.00000" xyz="-0.10000 0.10000 0.00000"/>
			<geometry>
				<cylinder length="0.14000" radius="0.04000"/>
			</geometry>
			<material name="mat_3_2">
				<color rgba="0.28125 0.51953 0.92578 1.00000" />
			</material>
		</visual>
		<collision>
			<origin rpy="1.57000 -0.00000 0.00000" xyz="0.00000 0.00000 -0.00000"/>
			<geometry>
				<cylinder length="0.30000" radius="0.05000"/>
			</geometry>
		</collision>
		<collision>
			<origin rpy="-0.00014 1.57033 -0.00014" xyz="0.10000 -0.15000 -0.00000"/>
			<geometry>
				<cylinder length="0.20000" radius="0.02000"/>
			</geometry>
		</collision>
		<collision>
			<origin rpy="-0.00014 1.57033 -0.00014" xyz="-0.10000 0.10000 0.00000"/>
			<geometry>
				<cylinder length="0.14000" radius="0.04000"/>
			</geometry>
		</collision>
	</link>
	<joint name="door_hinge" type="continuous">
		<parent link="frame"/>
		<child link="link0_2"/>
		<dynamics damping="1.0" friction="0.0001"/>
		<origin xyz="0.60000 0.00000 0.00000"/>
		<axis xyz="0.00000 0.00000 1.00000"/>
	</joint>
	<joint name="jointfix_1_2" type="fixed">
		<parent link="link0_2"/>
		<child link="door"/>
		<dynamics damping="1.0" friction="0.0001"/>
		<origin xyz="-0.31000 0.00000 0.00000"/>
		<axis xyz="0.00000 0.00000 0.00000"/>
	</joint>
	<joint name="latch" type="continuous">
		<parent link="door"/>
		<child link="link0_4"/>
		<dynamics damping="1.0" friction="0.0001"/>
		<origin xyz="-0.15000 0.00000 -0.02500"/>
		<axis xyz="0.00000 1.00000 0.00000"/>
	</joint>
	<joint name="jointfix_0_4" type="fixed">
		<parent link="link0_4"/>
		<child link="latch"/>
		<dynamics damping="1.0" friction="0.0001"/>
		<origin xyz="0.00000 0.00000 0.00000"/>
		<axis xyz="0.00000 0.00000 0.00000"/>
	</joint>
</robot>
